Workbook

Sheet Summary Page
A1: HIT SQUAD / PROJECT CONTROLS
A2: Produced by Hit Squad Project Controls · Confidential estimate package
A3: Madison CAT 2 (Pit Stop)
A4: Phillips 66 · Wood River — Roxana, IL · East Coast (PCA0001103)
A5: Produced Sep 4, 2026 | B5: 46269.757
A6: Rollup line | B6: Amount $ | C6: Man-hours (MH)
A7: Staff labor $ | B7: =Staff!K70 | C7: =Staff!B70
A8: Foremen labor $ | B8: =Foremen!K22 | C8: =Foremen!B22
A9: Direct labor $ | B9: =Direct!K22 | C9: =Direct!B22
A10: Support labor $ | B10: =Support!K22 | C10: =Support!B22
A11: Labor $ | B11: =SUM(B7,B8,B9,B10) | C11: =SUM(C7,C8,C9,C10)
A12: Per diem $ | B12: =SUM(Staff!D70,Foremen!D22,Direct!D22,Support!D22)
A13: Man-hours | C13: =SUM(C7,C8,C9,C10)
A14: Staff travel $ | B14: ='Staff Travel Cost'!E8
A15: Misc $ | B15: ='Misc Costs'!E10
A16: COE $ | B16: =COE!G11
A17: 6.5% markup | B17: 695.5
A19: ESTIMATE TOTAL $ | B19: =SUM(B11,B12,B14,B15,B16,B17) | C19: =SUM(C7,C8,C9,C10)

Sheet Staff
A1: HIT SQUAD / PROJECT CONTROLS
A2: Produced by Hit Squad Project Controls · Confidential estimate package
A3: Madison CAT 2 (Pit Stop)
A4: Phillips 66 · Wood River — Roxana, IL · East Coast (PCA0001103)
A5: Produced Sep 4, 2026 | B5: 46269.757
A6: Shift | B6: Total Billable | C6: Position | D6: Sub Total $ | E6: Rate | F6: Type | G6: ST Hrs | H6: OT Hrs | I6: DT Hrs | J6: PD Days | K6: Labor $ | L6: 46286 | M6: =L6+1 | N6: =M6+1 | O6: =N6+1 | P6: =O6+1 | Q6: =P6+1 | R6: =Q6+1 | S6: =R6+1 | T6: =S6+1 | ... AQ6: =AP6+1
A7: DAYSHIFT | B7: =G7+H7+I7 | C7: Superintendent PF 01 | D7: =K7 | F7: TITLE | G7: =B10 | H7: =B11 | I7: =B12 | J7: =B13 | K7: =D10+D11+D12 | OV7: cr-1787760932966-c9m84|day
F8: HC | L8: 1 | M8: 1 | N8: 1 | O8: 1 | P8: 1 | Q8: 0 | R8: 0 | S8: 1 | T8: 1 | U8: 1 | V8: 1 | W8: 1 | X8: 1 | Y8: 1 | Z8: 1 | AA8: 1 | AB8: 1 | AC8: 1 | AD8: 1 | AE8: 1 | AF8: 1 | AG8: 1 | AH8: 1 | AI8: 1 | AJ8: 1 | AK8: 1 | AL8: 0 | AM8: 0 | AN8: 1 | AO8: 1 | AP8: 1 | AQ8: 1 | OV8: cr-1787760932966-c9m84|day
A9: Enter Hours Per shift Here | F9: HPS | L9: 8 | M9: 8 | N9: 8 | O9: 8 | P9: 8 | Q9: 0 | R9: 0 | S9: 8 | T9: 8 | U9: 8 | V9: 12 | W9: 12 | X9: 12 | Y9: 12 | Z9: 12 | AA9: 12 | AB9: 12 | AC9: 12 | AD9: 12 | AE9: 12 | AF9: 12 | AG9: 12 | AH9: 12 | AI9: 12 | AJ9: 8 | AK9: 8 | AL9: 0 | AM9: 0 | AN9: 8 | AO9: 8 | AP9: 8 | AQ9: 8 | OV9: cr-1787760932966-c9m84|day
B10: =SUM(L10:AQ10) | D10: =B10*E10 | E10: ='Rate Tables'!C7 | F10: ST | L10: =IF(L$6="","",IF(WEEKDAY(L$6,1)=1,0,MIN(8,L9)*L8)) | M10: =IF(M$6="","",IF(WEEKDAY(M$6,1)=1,0,MIN(8,M9)*M8)) | N10: =IF(N$6="","",IF(WEEKDAY(N$6,1)=1,0,MIN(8,N9)*N8)) | O10: =IF(O$6="","",IF(WEEKDAY(O$6,1)=1,0,MIN(8,O9)*O8)) | P10: =IF(P$6="","",IF(WEEKDAY(P$6,1)=1,0,MIN(8,P9)*P8)) | Q10: =IF(Q$6="","",IF(WEEKDAY(Q$6,1)=1,0,MIN(8,Q9)*Q8)) | R10: =IF(R$6="","",IF(WEEKDAY(R$6,1)=1,0,MIN(8,R9)*R8)) | S10: =IF(S$6="","",IF(WEEKDAY(S$6,1)=1,0,MIN(8,S9)*S8)) | ... AQ10: =IF(AQ$6="","",IF(WEEKDAY(AQ$6,1)=1,0,MIN(8,AQ9)*AQ8)) | OV10: cr-1787760932966-c9m84|day
B11: =SUM(L11:AQ11) | D11: =B11*E11 | E11: ='Rate Tables'!D7 | F11: OT | L11: =IF(L$6="","",IF(WEEKDAY(L$6,1)=1,0,MAX(0,L9-8)*L8)) | M11: =IF(M$6="","",IF(WEEKDAY(M$6,1)=1,0,MAX(0,M9-8)*M8)) | N11: =IF(N$6="","",IF(WEEKDAY(N$6,1)=1,0,MAX(0,N9-8)*N8)) | O11: =IF(O$6="","",IF(WEEKDAY(O$6,1)=1,0,MAX(0,O9-8)*O8)) | P11: =IF(P$6="","",IF(WEEKDAY(P$6,1)=1,0,MAX(0,P9-8)*P8)) | Q11: =IF(Q$6="","",IF(WEEKDAY(Q$6,1)=1,0,MAX(0,Q9-8)*Q8)) | R11: =IF(R$6="","",IF(WEEKDAY(R$6,1)=1,0,MAX(0,R9-8)*R8)) | S11: =IF(S$6="","",IF(WEEKDAY(S$6,1)=1,0,MAX(0,S9-8)*S8)) | ... AQ11: =IF(AQ$6="","",IF(WEEKDAY(AQ$6,1)=1,0,MAX(0,AQ9-8)*AQ8)) | OV11: cr-1787760932966-c9m84|day
B12: =SUM(L12:AQ12) | D12: =B12*E12 | E12: ='Rate Tables'!E7 | F12: DT | L12: =IF(L$6="","",IF(WEEKDAY(L$6,1)=1,L9*L8,0)) | M12: =IF(M$6="","",IF(WEEKDAY(M$6,1)=1,M9*M8,0)) | N12: =IF(N$6="","",IF(WEEKDAY(N$6,1)=1,N9*N8,0)) | O12: =IF(O$6="","",IF(WEEKDAY(O$6,1)=1,O9*O8,0)) | P12: =IF(P$6="","",IF(WEEKDAY(P$6,1)=1,P9*P8,0)) | Q12: =IF(Q$6="","",IF(WEEKDAY(Q$6,1)=1,Q9*Q8,0)) | R12: =IF(R$6="","",IF(WEEKDAY(R$6,1)=1,R9*R8,0)) | S12: =IF(S$6="","",IF(WEEKDAY(S$6,1)=1,S9*S8,0)) | ... AQ12: =IF(AQ$6="","",IF(WEEKDAY(AQ$6,1)=1,AQ9*AQ8,0)) | OV12: cr-1787760932966-c9m84|day
B13: =SUM(L13:AQ13) | D13: =B13*E13 | E13: 140 | F13: PD | L13: 1 | M13: 1 | N13: 1 | O13: 1 | P13: 1 | Q13: 0 | R13: 0 | S13: 1 | T13: 1 | U13: 1 | V13: 1 | W13: 1 | X13: 1 | Y13: 1 | Z13: 1 | AA13: 1 | AB13: 1 | AC13: 1 | AD13: 1 | AE13: 1 | AF13: 1 | AG13: 1 | AH13: 1 | AI13: 1 | AJ13: 0 | AK13: 0 | AL13: 0 | AM13: 0 | AN13: 0 | AO13: 0 | AP13: 0 | AQ13: 0 | OV13: cr-1787760932966-c9m84|day
A15: NIGHTSHIFT | B15: =G15+H15+I15 | C15: Superintendent PF 01 | D15: =K15 | F15: TITLE | G15: =B18 | H15: =B19 | I15: =B20 | J15: =B21 | K15: =D18+D19+D20 | OV15: cr-1787760932966-c9m84|night
F16: HC | L16: 1 | M16: 1 | N16: 1 | O16: 1 | P16: 1 | Q16: 0 | R16: 0 | S16: 1 | T16: 1 | U16: 1 | V16: 1 | W16: 1 | X16: 1 | Y16: 1 | Z16: 1 | AA16: 1 | AB16: 1 | AC16: 1 | AD16: 1 | AE16: 1 | AF16: 1 | AG16: 1 | AH16: 1 | AI16: 1 | AJ16: 0 | AK16: 0 | AL16: 0 | AM16: 0 | AN16: 0 | AO16: 0 | AP16: 0 | AQ16: 0 | OV16: cr-1787760932966-c9m84|night
A17: Enter Hours Per shift Here | F17: HPS | L17: 8 | M17: 8 | N17: 8 | O17: 8 | P17: 8 | Q17: 0 | R17: 0 | S17: 8 | T17: 8 | U17: 8 | V17: 12 | W17: 12 | X17: 12 | Y17: 12 | Z17: 12 | AA17: 12 | AB17: 12 | AC17: 12 | AD17: 12 | AE17: 12 | AF17: 12 | AG17: 12 | AH17: 12 | AI17: 12 | AJ17: 0 | AK17: 0 | AL17: 0 | AM17: 0 | AN17: 0 | AO17: 0 | AP17: 0 | AQ17: 0 | OV17: cr-1787760932966-c9m84|night
B18: =SUM(L18:AQ18) | D18: =B18*E18 | E18: ='Rate Tables'!C7 | F18: ST | L18: =IF(L$6="","",IF(WEEKDAY(L$6,1)=1,0,MIN(8,L17)*L16)) | M18: =IF(M$6="","",IF(WEEKDAY(M$6,1)=1,0,MIN(8,M17)*M16)) | N18: =IF(N$6="","",IF(WEEKDAY(N$6,1)=1,0,MIN(8,N17)*N16)) | O18: =IF(O$6="","",IF(WEEKDAY(O$6,1)=1,0,MIN(8,O17)*O16)) | P18: =IF(P$6="","",IF(WEEKDAY(P$6,1)=1,0,MIN(8,P17)*P16)) | Q18: =IF(Q$6="","",IF(WEEKDAY(Q$6,1)=1,0,MIN(8,Q17)*Q16)) | R18: =IF(R$6="","",IF(WEEKDAY(R$6,1)=1,0,MIN(8,R17)*R16)) | S18: =IF(S$6="","",IF(WEEKDAY(S$6,1)=1,0,MIN(8,S17)*S16)) | ... AQ18: =IF(AQ$6="","",IF(WEEKDAY(AQ$6,1)=1,0,MIN(8,AQ17)*AQ16)) | OV18: cr-1787760932966-c9m84|night
B19: =SUM(L19:AQ19) | D19: =B19*E19 | E19: ='Rate Tables'!D7 | F19: OT | L19: =IF(L$6="","",IF(WEEKDAY(L$6,1)=1,0,MAX(0,L17-8)*L16)) | M19: =IF(M$6="","",IF(WEEKDAY(M$6,1)=1,0,MAX(0,M17-8)*M16)) | N19: =IF(N$6="","",IF(WEEKDAY(N$6,1)=1,0,MAX(0,N17-8)*N16)) | O19: =IF(O$6="","",IF(WEEKDAY(O$6,1)=1,0,MAX(0,O17-8)*O16)) | P19: =IF(P$6="","",IF(WEEKDAY(P$6,1)=1,0,MAX(0,P17-8)*P16)) | Q19: =IF(Q$6="","",IF(WEEKDAY(Q$6,1)=1,0,MAX(0,Q17-8)*Q16)) | R19: =IF(R$6="","",IF(WEEKDAY(R$6,1)=1,0,MAX(0,R17-8)*R16)) | S19: =IF(S$6="","",IF(WEEKDAY(S$6,1)=1,0,MAX(0,S17-8)*S16)) | ... AQ19: =IF(AQ$6="","",IF(WEEKDAY(AQ$6,1)=1,0,MAX(0,AQ17-8)*AQ16)) | OV19: cr-1787760932966-c9m84|night
B20: =SUM(L20:AQ20) | D20: =B20*E20 | E20: ='Rate Tables'!E7 | F20: DT | L20: =IF(L$6="","",IF(WEEKDAY(L$6,1)=1,L17*L16,0)) | M20: =IF(M$6="","",IF(WEEKDAY(M$6,1)=1,M17*M16,0)) | N20: =IF(N$6="","",IF(WEEKDAY(N$6,1)=1,N17*N16,0)) | O20: =IF(O$6="","",IF(WEEKDAY(O$6,1)=1,O17*O16,0)) | P20: =IF(P$6="","",IF(WEEKDAY(P$6,1)=1,P17*P16,0)) | Q20: =IF(Q$6="","",IF(WEEKDAY(Q$6,1)=1,Q17*Q16,0)) | R20: =IF(R$6="","",IF(WEEKDAY(R$6,1)=1,R17*R16,0)) | S20: =IF(S$6="","",IF(WEEKDAY(S$6,1)=1,S17*S16,0)) | ... AQ20: =IF(AQ$6="","",IF(WEEKDAY(AQ$6,1)=1,AQ17*AQ16,0)) | OV20: cr-1787760932966-c9m84|night
B21: =SUM(L21:AQ21) | D21: =B21*E21 | E21: 140 | F21: PD | L21: 1 | M21: 1 | N21: 1 | O21: 1 | P21: 1 | Q21: 0 | R21: 0 | S21: 1 | T21: 1 | U21: 1 | V21: 1 | W21: 1 | X21: 1 | Y21: 1 | Z21: 1 | AA21: 1 | AB21: 1 | AC21: 1 | AD21: 1 | AE21: 1 | AF21: 1 | AG21: 1 | AH21: 1 | AI21: 1 | AJ21: 0 | AK21: 0 | AL21: 0 | AM21: 0 | AN21: 0 | AO21: 0 | AP21: 0 | AQ21: 0 | OV21: cr-1787760932966-c9m84|night
A23: DAYSHIFT | B23: =G23+H23+I23 | C23: COORDINATOR QA-QC 1 | D23: =K23 | F23: TITLE | G23: =B26 | H23: =B27 | I23: =B28 | J23: =B29 | K23: =D26+D27+D28 | OV23: cr-1787762352222-vw0iw|day
F24: HC | L24: 1 | M24: 1 | N24: 1 | O24: 1 | P24: 1 | Q24: 0 | R24: 0 | S24: 1 | T24: 1 | U24: 1 | V24: 1 | W24: 1 | X24: 1 | Y24: 1 | Z24: 1 | AA24: 1 | AB24: 1 | AC24: 1 | AD24: 1 | AE24: 1 | AF24: 1 | AG24: 1 | AH24: 1 | AI24: 1 | AJ24: 1 | AK24: 1 | AL24: 0 | AM24: 0 | AN24: 1 | AO24: 1 | AP24: 1 | AQ24: 1 | OV24: cr-1787762352222-vw0iw|day
A25: Enter Hours Per shift Here | F25: HPS | L25: 8 | M25: 8 | N25: 8 | O25: 8 | P25: 8 | Q25: 0 | R25: 0 | S25: 8 | T25: 8 | U25: 8 | V25: 12 | W25: 12 | X25: 12 | Y25: 12 | Z25: 12 | AA25: 12 | AB25: 12 | AC25: 12 | AD25: 12 | AE25: 12 | AF25: 12 | AG25: 12 | AH25: 12 | AI25: 12 | AJ25: 8 | AK25: 8 | AL25: 0 | AM25: 0 | AN25: 8 | AO25: 8 | AP25: 8 | AQ25: 8 | OV25: cr-1787762352222-vw0iw|day
B26: =SUM(L26:AQ26) | D26: =B26*E26 | E26: ='Rate Tables'!C8 | F26: ST | L26: =IF(L$6="","",IF(WEEKDAY(L$6,1)=1,0,MIN(8,L25)*L24)) | M26: =IF(M$6="","",IF(WEEKDAY(M$6,1)=1,0,MIN(8,M25)*M24)) | N26: =IF(N$6="","",IF(WEEKDAY(N$6,1)=1,0,MIN(8,N25)*N24)) | O26: =IF(O$6="","",IF(WEEKDAY(O$6,1)=1,0,MIN(8,O25)*O24)) | P26: =IF(P$6="","",IF(WEEKDAY(P$6,1)=1,0,MIN(8,P25)*P24)) | Q26: =IF(Q$6="","",IF(WEEKDAY(Q$6,1)=1,0,MIN(8,Q25)*Q24)) | R26: =IF(R$6="","",IF(WEEKDAY(R$6,1)=1,0,MIN(8,R25)*R24)) | S26: =IF(S$6="","",IF(WEEKDAY(S$6,1)=1,0,MIN(8,S25)*S24)) | ... AQ26: =IF(AQ$6="","",IF(WEEKDAY(AQ$6,1)=1,0,MIN(8,AQ25)*AQ24)) | OV26: cr-1787762352222-vw0iw|day
B27: =SUM(L27:AQ27) | D27: =B27*E27 | E27: ='Rate Tables'!D8 | F27: OT | L27: =IF(L$6="","",IF(WEEKDAY(L$6,1)=1,0,MAX(0,L25-8)*L24)) | M27: =IF(M$6="","",IF(WEEKDAY(M$6,1)=1,0,MAX(0,M25-8)*M24)) | N27: =IF(N$6="","",IF(WEEKDAY(N$6,1)=1,0,MAX(0,N25-8)*N24)) | O27: =IF(O$6="","",IF(WEEKDAY(O$6,1)=1,0,MAX(0,O25-8)*O24)) | P27: =IF(P$6="","",IF(WEEKDAY(P$6,1)=1,0,MAX(0,P25-8)*P24)) | Q27: =IF(Q$6="","",IF(WEEKDAY(Q$6,1)=1,0,MAX(0,Q25-8)*Q24)) | R27: =IF(R$6="","",IF(WEEKDAY(R$6,1)=1,0,MAX(0,R25-8)*R24)) | S27: =IF(S$6="","",IF(WEEKDAY(S$6,1)=1,0,MAX(0,S25-8)*S24)) | ... AQ27: =IF(AQ$6="","",IF(WEEKDAY(AQ$6,1)=1,0,MAX(0,AQ25-8)*AQ24)) | OV27: cr-1787762352222-vw0iw|day
B28: =SUM(L28:AQ28) | D28: =B28*E28 | E28: ='Rate Tables'!E8 | F28: DT | L28: =IF(L$6="","",IF(WEEKDAY(L$6,1)=1,L25*L24,0)) | M28: =IF(M$6="","",IF(WEEKDAY(M$6,1)=1,M25*M24,0)) | N28: =IF(N$6="","",IF(WEEKDAY(N$6,1)=1,N25*N24,0)) | O28: =IF(O$6="","",IF(WEEKDAY(O$6,1)=1,O25*O24,0)) | P28: =IF(P$6="","",IF(WEEKDAY(P$6,1)=1,P25*P24,0)) | Q28: =IF(Q$6="","",IF(WEEKDAY(Q$6,1)=1,Q25*Q24,0)) | R28: =IF(R$6="","",IF(WEEKDAY(R$6,1)=1,R25*R24,0)) | S28: =IF(S$6="","",IF(WEEKDAY(S$6,1)=1,S25*S24,0)) | ... AQ28: =IF(AQ$6="","",IF(WEEKDAY(AQ$6,1)=1,AQ25*AQ24,0)) | OV28: cr-1787762352222-vw0iw|day
B29: =SUM(L29:AQ29) | D29: =B29*E29 | E29: 140 | F29: PD | L29: 1 | M29: 1 | N29: 1 | O29: 1 | P29: 1 | Q29: 0 | R29: 0 | S29: 1 | T29: 1 | U29: 1 | V29: 1 | W29: 1 | X29: 1 | Y29: 1 | Z29: 1 | AA29: 1 | AB29: 1 | AC29: 1 | AD29: 1 | AE29: 1 | AF29: 1 | AG29: 1 | AH29: 1 | AI29: 1 | AJ29: 0 | AK29: 0 | AL29: 0 | AM29: 0 | AN29: 0 | AO29: 0 | AP29: 0 | AQ29: 0 | OV29: cr-1787762352222-vw0iw|day
A31: NIGHTSHIFT | B31: =G31+H31+I31 | C31: COORDINATOR QA-QC 1 | D31: =K31 | F31: TITLE | G31: =B34 | H31: =B35 | I31: =B36 | J31: =B37 | K31: =D34+D35+D36 | OV31: cr-1787762352222-vw0iw|night
F32: HC | L32: 1 | M32: 1 | N32: 1 | O32: 1 | P32: 1 | Q32: 0 | R32: 0 | S32: 1 | T32: 1 | U32: 1 | V32: 1 | W32: 1 | X32: 1 | Y32: 1 | Z32: 1 | AA32: 1 | AB32: 1 | AC32: 1 | AD32: 1 | AE32: 1 | AF32: 1 | AG32: 1 | AH32: 1 | AI32: 1 | AJ32: 0 | AK32: 0 | AL32: 0 | AM32: 0 | AN32: 0 | AO32: 0 | AP32: 0 | AQ32: 0 | OV32: cr-1787762352222-vw0iw|night
A33: Enter Hours Per shift Here | F33: HPS | L33: 8 | M33: 8 | N33: 8 | O33: 8 | P33: 8 | Q33: 0 | R33: 0 | S33: 8 | T33: 8 | U33: 8 | V33: 12 | W33: 12 | X33: 12 | Y33: 12 | Z33: 12 | AA33: 12 | AB33: 12 | AC33: 12 | AD33: 12 | AE33: 12 | AF33: 12 | AG33: 12 | AH33: 12 | AI33: 12 | AJ33: 0 | AK33: 0 | AL33: 0 | AM33: 0 | AN33: 0 | AO33: 0 | AP33: 0 | AQ33: 0 | OV33: cr-1787762352222-vw0iw|night
B34: =SUM(L34:AQ34) | D34: =B34*E34 | E34: ='Rate Tables'!C8 | F34: ST | L34: =IF(L$6="","",IF(WEEKDAY(L$6,1)=1,0,MIN(8,L33)*L32)) | M34: =IF(M$6="","",IF(WEEKDAY(M$6,1)=1,0,MIN(8,M33)*M32)) | N34: =IF(N$6="","",IF(WEEKDAY(N$6,1)=1,0,MIN(8,N33)*N32)) | O34: =IF(O$6="","",IF(WEEKDAY(O$6,1)=1,0,MIN(8,O33)*O32)) | P34: =IF(P$6="","",IF(WEEKDAY(P$6,1)=1,0,MIN(8,P33)*P32)) | Q34: =IF(Q$6="","",IF(WEEKDAY(Q$6,1)=1,0,MIN(8,Q33)*Q32)) | R34: =IF(R$6="","",IF(WEEKDAY(R$6,1)=1,0,MIN(8,R33)*R32)) | S34: =IF(S$6="","",IF(WEEKDAY(S$6,1)=1,0,MIN(8,S33)*S32)) | ... AQ34: =IF(AQ$6="","",IF(WEEKDAY(AQ$6,1)=1,0,MIN(8,AQ33)*AQ32)) | OV34: cr-1787762352222-vw0iw|night
B35: =SUM(L35:AQ35) | D35: =B35*E35 | E35: ='Rate Tables'!D8 | F35: OT | L35: =IF(L$6="","",IF(WEEKDAY(L$6,1)=1,0,MAX(0,L33-8)*L32)) | M35: =IF(M$6="","",IF(WEEKDAY(M$6,1)=1,0,MAX(0,M33-8)*M32)) | N35: =IF(N$6="","",IF(WEEKDAY(N$6,1)=1,0,MAX(0,N33-8)*N32)) | O35: =IF(O$6="","",IF(WEEKDAY(O$6,1)=1,0,MAX(0,O33-8)*O32)) | P35: =IF(P$6="","",IF(WEEKDAY(P$6,1)=1,0,MAX(0,P33-8)*P32)) | Q35: =IF(Q$6="","",IF(WEEKDAY(Q$6,1)=1,0,MAX(0,Q33-8)*Q32)) | R35: =IF(R$6="","",IF(WEEKDAY(R$6,1)=1,0,MAX(0,R33-8)*R32)) | S35: =IF(S$6="","",IF(WEEKDAY(S$6,1)=1,0,MAX(0,S33-8)*S32)) | ... AQ35: =IF(AQ$6="","",IF(WEEKDAY(AQ$6,1)=1,0,MAX(0,AQ33-8)*AQ32)) | OV35: cr-1787762352222-vw0iw|night
B36: =SUM(L36:AQ36) | D36: =B36*E36 | E36: ='Rate Tables'!E8 | F36: DT | L36: =IF(L$6="","",IF(WEEKDAY(L$6,1)=1,L33*L32,0)) | M36: =IF(M$6="","",IF(WEEKDAY(M$6,1)=1,M33*M32,0)) | N36: =IF(N$6="","",IF(WEEKDAY(N$6,1)=1,N33*N32,0)) | O36: =IF(O$6="","",IF(WEEKDAY(O$6,1)=1,O33*O32,0)) | P36: =IF(P$6="","",IF(WEEKDAY(P$6,1)=1,P33*P32,0)) | Q36: =IF(Q$6="","",IF(WEEKDAY(Q$6,1)=1,Q33*Q32,0)) | R36: =IF(R$6="","",IF(WEEKDAY(R$6,1)=1,R33*R32,0)) | S36: =IF(S$6="","",IF(WEEKDAY(S$6,1)=1,S33*S32,0)) | ... AQ36: =IF(AQ$6="","",IF(WEEKDAY(AQ$6,1)=1,AQ33*AQ32,0)) | OV36: cr-1787762352222-vw0iw|night
B37: =SUM(L37:AQ37) | D37: =B37*E37 | E37: 140 | F37: PD | L37: 1 | M37: 1 | N37: 1 | O37: 1 | P37: 1 | Q37: 0 | R37: 0 | S37: 1 | T37: 1 | U37: 1 | V37: 1 | W37: 1 | X37: 1 | Y37: 1 | Z37: 1 | AA37: 1 | AB37: 1 | AC37: 1 | AD37: 1 | AE37: 1 | AF37: 1 | AG37: 1 | AH37: 1 | AI37: 1 | AJ37: 0 | AK37: 0 | AL37: 0 | AM37: 0 | AN37: 0 | AO37: 0 | AP37: 0 | AQ37: 0 | OV37: cr-1787762352222-vw0iw|night
A39: DAYSHIFT | B39: =G39+H39+I39 | C39: COORDINATOR SAFETY 01 | D39: =K39 | F39: TITLE | G39: =B42 | H39: =B43 | I39: =B44 | J39: =B45 | K39: =D42+D43+D44 | OV39: cr-1787762351054-x15wg|day
F40: HC | L40: 1 | M40: 1 | N40: 1 | O40: 1 | P40: 1 | Q40: 0 | R40: 0 | S40: 1 | T40: 1 | U40: 1 | V40: 1 | W40: 1 | X40: 1 | Y40: 1 | Z40: 1 | AA40: 1 | AB40: 1 | AC40: 1 | AD40: 1 | AE40: 1 | AF40: 1 | AG40: 1 | AH40: 1 | AI40: 1 | AJ40: 1 | AK40: 1 | AL40: 0 | AM40: 0 | AN40: 1 | AO40: 1 | AP40: 1 | AQ40: 1 | OV40: cr-1787762351054-x15wg|day
A41: Enter Hours Per shift Here | F41: HPS | L41: 8 | M41: 8 | N41: 8 | O41: 8 | P41: 8 | Q41: 0 | R41: 0 | S41: 8 | T41: 8 | U41: 8 | V41: 12 | W41: 12 | X41: 12 | Y41: 12 | Z41: 12 | AA41: 12 | AB41: 12 | AC41: 12 | AD41: 12 | AE41: 12 | AF41: 12 | AG41: 12 | AH41: 12 | AI41: 12 | AJ41: 8 | AK41: 8 | AL41: 0 | AM41: 0 | AN41: 8 | AO41: 8 | AP41: 8 | AQ41: 8 | OV41: cr-1787762351054-x15wg|day
B42: =SUM(L42:AQ42) | D42: =B42*E42 | E42: ='Rate Tables'!C9 | F42: ST | L42: =IF(L$6="","",IF(WEEKDAY(L$6,1)=1,0,MIN(8,L41)*L40)) | M42: =IF(M$6="","",IF(WEEKDAY(M$6,1)=1,0,MIN(8,M41)*M40)) | N42: =IF(N$6="","",IF(WEEKDAY(N$6,1)=1,0,MIN(8,N41)*N40)) | O42: =IF(O$6="","",IF(WEEKDAY(O$6,1)=1,0,MIN(8,O41)*O40)) | P42: =IF(P$6="","",IF(WEEKDAY(P$6,1)=1,0,MIN(8,P41)*P40)) | Q42: =IF(Q$6="","",IF(WEEKDAY(Q$6,1)=1,0,MIN(8,Q41)*Q40)) | R42: =IF(R$6="","",IF(WEEKDAY(R$6,1)=1,0,MIN(8,R41)*R40)) | S42: =IF(S$6="","",IF(WEEKDAY(S$6,1)=1,0,MIN(8,S41)*S40)) | ... AQ42: =IF(AQ$6="","",IF(WEEKDAY(AQ$6,1)=1,0,MIN(8,AQ41)*AQ40)) | OV42: cr-1787762351054-x15wg|day
B43: =SUM(L43:AQ43) | D43: =B43*E43 | E43: ='Rate Tables'!D9 | F43: OT | L43: =IF(L$6="","",IF(WEEKDAY(L$6,1)=1,0,MAX(0,L41-8)*L40)) | M43: =IF(M$6="","",IF(WEEKDAY(M$6,1)=1,0,MAX(0,M41-8)*M40)) | N43: =IF(N$6="","",IF(WEEKDAY(N$6,1)=1,0,MAX(0,N41-8)*N40)) | O43: =IF(O$6="","",IF(WEEKDAY(O$6,1)=1,0,MAX(0,O41-8)*O40)) | P43: =IF(P$6="","",IF(WEEKDAY(P$6,1)=1,0,MAX(0,P41-8)*P40)) | Q43: =IF(Q$6="","",IF(WEEKDAY(Q$6,1)=1,0,MAX(0,Q41-8)*Q40)) | R43: =IF(R$6="","",IF(WEEKDAY(R$6,1)=1,0,MAX(0,R41-8)*R40)) | S43: =IF(S$6="","",IF(WEEKDAY(S$6,1)=1,0,MAX(0,S41-8)*S40)) | ... AQ43: =IF(AQ$6="","",IF(WEEKDAY(AQ$6,1)=1,0,MAX(0,AQ41-8)*AQ40)) | OV43: cr-1787762351054-x15wg|day
B44: =SUM(L44:AQ44) | D44: =B44*E44 | E44: ='Rate Tables'!E9 | F44: DT | L44: =IF(L$6="","",IF(WEEKDAY(L$6,1)=1,L41*L40,0)) | M44: =IF(M$6="","",IF(WEEKDAY(M$6,1)=1,M41*M40,0)) | N44: =IF(N$6="","",IF(WEEKDAY(N$6,1)=1,N41*N40,0)) | O44: =IF(O$6="","",IF(WEEKDAY(O$6,1)=1,O41*O40,0)) | P44: =IF(P$6="","",IF(WEEKDAY(P$6,1)=1,P41*P40,0)) | Q44: =IF(Q$6="","",IF(WEEKDAY(Q$6,1)=1,Q41*Q40,0)) | R44: =IF(R$6="","",IF(WEEKDAY(R$6,1)=1,R41*R40,0)) | S44: =IF(S$6="","",IF(WEEKDAY(S$6,1)=1,S41*S40,0)) | ... AQ44: =IF(AQ$6="","",IF(WEEKDAY(AQ$6,1)=1,AQ41*AQ40,0)) | OV44: cr-1787762351054-x15wg|day
...

Sheet Foremen
A1: HIT SQUAD / PROJECT CONTROLS
A2: Produced by Hit Squad Project Controls · Confidential estimate package
A3: Madison CAT 2 (Pit Stop)
A4: Phillips 66 · Wood River — Roxana, IL · East Coast (PCA0001103)
A5: Produced Sep 4, 2026 | B5: 46269.757
A6: Shift | B6: Total Billable | C6: Position | D6: Sub Total $ | E6: Rate | F6: Type | G6: ST Hrs | H6: OT Hrs | I6: DT Hrs | J6: PD Days | K6: Labor $ | L6: 46286 | M6: =L6+1 | N6: =M6+1 | O6: =N6+1 | P6: =O6+1 | Q6: =P6+1 | R6: =Q6+1 | S6: =R6+1 | T6: =S6+1 | ... AQ6: =AP6+1
A7: DAYSHIFT | B7: =G7+H7+I7 | C7: Pipefitter Foreman | D7: =K7 | F7: TITLE | G7: =B10 | H7: =B11 | I7: =B12 | J7: =B13 | K7: =D10+D11+D12 | OV7: cr-1787763837290-77aw3|day
F8: HC | L8: 2 | M8: 2 | N8: 2 | O8: 2 | P8: 2 | Q8: 0 | R8: 0 | S8: 2 | T8: 2 | U8: 2 | V8: 2 | W8: 2 | X8: 2 | Y8: 2 | Z8: 2 | AA8: 2 | AB8: 2 | AC8: 2 | AD8: 2 | AE8: 2 | AF8: 2 | AG8: 2 | AH8: 2 | AI8: 2 | AJ8: 1 | AK8: 1 | AL8: 0 | AM8: 0 | AN8: 1 | AO8: 1 | AP8: 1 | AQ8: 1 | OV8: cr-1787763837290-77aw3|day
A9: Enter Hours Per shift Here | F9: HPS | L9: 8 | M9: 8 | N9: 8 | O9: 8 | P9: 8 | Q9: 0 | R9: 0 | S9: 8 | T9: 8 | U9: 8 | V9: 12 | W9: 12 | X9: 12 | Y9: 12 | Z9: 12 | AA9: 12 | AB9: 12 | AC9: 12 | AD9: 12 | AE9: 12 | AF9: 12 | AG9: 12 | AH9: 12 | AI9: 12 | AJ9: 8 | AK9: 8 | AL9: 0 | AM9: 0 | AN9: 8 | AO9: 8 | AP9: 8 | AQ9: 8 | OV9: cr-1787763837290-77aw3|day
B10: =SUM(L10:AQ10) | D10: =B10*E10 | E10: ='Rate Tables'!C11 | F10: ST | L10: =IF(L$6="","",IF(OR(WEEKDAY(L$6,1)=1,WEEKDAY(L$6,1)=7),0,MIN(8,L9)*L8)) | M10: =IF(M$6="","",IF(OR(WEEKDAY(M$6,1)=1,WEEKDAY(M$6,1)=7),0,MIN(8,M9)*M8)) | N10: =IF(N$6="","",IF(OR(WEEKDAY(N$6,1)=1,WEEKDAY(N$6,1)=7),0,MIN(8,N9)*N8)) | O10: =IF(O$6="","",IF(OR(WEEKDAY(O$6,1)=1,WEEKDAY(O$6,1)=7),0,MIN(8,O9)*O8)) | P10: =IF(P$6="","",IF(OR(WEEKDAY(P$6,1)=1,WEEKDAY(P$6,1)=7),0,MIN(8,P9)*P8)) | Q10: =IF(Q$6="","",IF(OR(WEEKDAY(Q$6,1)=1,WEEKDAY(Q$6,1)=7),0,MIN(8,Q9)*Q8)) | R10: =IF(R$6="","",IF(OR(WEEKDAY(R$6,1)=1,WEEKDAY(R$6,1)=7),0,MIN(8,R9)*R8)) | S10: =IF(S$6="","",IF(OR(WEEKDAY(S$6,1)=1,WEEKDAY(S$6,1)=7),0,MIN(8,S9)*S8)) | ... AQ10: =IF(AQ$6="","",IF(OR(WEEKDAY(AQ$6,1)=1,WEEKDAY(AQ$6,1)=7),0,MIN(8,AQ9)*AQ8)) | OV10: cr-1787763837290-77aw3|day
B11: =SUM(L11:AQ11) | D11: =B11*E11 | E11: ='Rate Tables'!D11 | F11: OT | L11: =IF(L$6="","",IF(WEEKDAY(L$6,1)=1,0,IF(WEEKDAY(L$6,1)=7,L9*L8,MAX(0,L9-8)*L8))) | M11: =IF(M$6="","",IF(WEEKDAY(M$6,1)=1,0,IF(WEEKDAY(M$6,1)=7,M9*M8,MAX(0,M9-8)*M8))) | N11: =IF(N$6="","",IF(WEEKDAY(N$6,1)=1,0,IF(WEEKDAY(N$6,1)=7,N9*N8,MAX(0,N9-8)*N8))) | O11: =IF(O$6="","",IF(WEEKDAY(O$6,1)=1,0,IF(WEEKDAY(O$6,1)=7,O9*O8,MAX(0,O9-8)*O8))) | P11: =IF(P$6="","",IF(WEEKDAY(P$6,1)=1,0,IF(WEEKDAY(P$6,1)=7,P9*P8,MAX(0,P9-8)*P8))) | Q11: =IF(Q$6="","",IF(WEEKDAY(Q$6,1)=1,0,IF(WEEKDAY(Q$6,1)=7,Q9*Q8,MAX(0,Q9-8)*Q8))) | R11: =IF(R$6="","",IF(WEEKDAY(R$6,1)=1,0,IF(WEEKDAY(R$6,1)=7,R9*R8,MAX(0,R9-8)*R8))) | S11: =IF(S$6="","",IF(WEEKDAY(S$6,1)=1,0,IF(WEEKDAY(S$6,1)=7,S9*S8,MAX(0,S9-8)*S8))) | ... AQ11: =IF(AQ$6="","",IF(WEEKDAY(AQ$6,1)=1,0,IF(WEEKDAY(AQ$6,1)=7,AQ9*AQ8,MAX(0,AQ9-8)*AQ8))) | OV11: cr-1787763837290-77aw3|day
B12: =SUM(L12:AQ12) | D12: =B12*E12 | E12: ='Rate Tables'!E11 | F12: DT | L12: =IF(L$6="","",IF(WEEKDAY(L$6,1)=1,L9*L8,0)) | M12: =IF(M$6="","",IF(WEEKDAY(M$6,1)=1,M9*M8,0)) | N12: =IF(N$6="","",IF(WEEKDAY(N$6,1)=1,N9*N8,0)) | O12: =IF(O$6="","",IF(WEEKDAY(O$6,1)=1,O9*O8,0)) | P12: =IF(P$6="","",IF(WEEKDAY(P$6,1)=1,P9*P8,0)) | Q12: =IF(Q$6="","",IF(WEEKDAY(Q$6,1)=1,Q9*Q8,0)) | R12: =IF(R$6="","",IF(WEEKDAY(R$6,1)=1,R9*R8,0)) | S12: =IF(S$6="","",IF(WEEKDAY(S$6,1)=1,S9*S8,0)) | ... AQ12: =IF(AQ$6="","",IF(WEEKDAY(AQ$6,1)=1,AQ9*AQ8,0)) | OV12: cr-1787763837290-77aw3|day
B13: =SUM(L13:AQ13) | D13: =B13*E13 | E13: 130 | F13: PD | L13: 2 | M13: 2 | N13: 2 | O13: 2 | P13: 2 | Q13: 0 | R13: 0 | S13: 2 | T13: 2 | U13: 2 | V13: 2 | W13: 2 | X13: 2 | Y13: 2 | Z13: 2 | AA13: 2 | AB13: 2 | AC13: 2 | AD13: 2 | AE13: 2 | AF13: 2 | AG13: 2 | AH13: 2 | AI13: 2 | AJ13: 1 | AK13: 1 | AL13: 0 | AM13: 0 | AN13: 1 | AO13: 1 | AP13: 1 | AQ13: 1 | OV13: cr-1787763837290-77aw3|day
A15: NIGHTSHIFT | B15: =G15+H15+I15 | C15: Pipefitter Foreman | D15: =K15 | F15: TITLE | G15: =B18 | H15: =B19 | I15: =B20 | J15: =B21 | K15: =D18+D19+D20 | OV15: cr-1787763837290-77aw3|night
F16: HC | L16: 2 | M16: 2 | N16: 2 | O16: 2 | P16: 2 | Q16: 0 | R16: 0 | S16: 2 | T16: 2 | U16: 2 | V16: 2 | W16: 2 | X16: 2 | Y16: 2 | Z16: 2 | AA16: 2 | AB16: 2 | AC16: 2 | AD16: 2 | AE16: 2 | AF16: 2 | AG16: 2 | AH16: 2 | AI16: 2 | AJ16: 0 | AK16: 0 | AL16: 0 | AM16: 0 | AN16: 0 | AO16: 0 | AP16: 0 | AQ16: 0 | OV16: cr-1787763837290-77aw3|night
A17: Enter Hours Per shift Here | F17: HPS | L17: 8 | M17: 8 | N17: 8 | O17: 8 | P17: 8 | Q17: 0 | R17: 0 | S17: 8 | T17: 8 | U17: 8 | V17: 12 | W17: 12 | X17: 12 | Y17: 12 | Z17: 12 | AA17: 12 | AB17: 12 | AC17: 12 | AD17: 12 | AE17: 12 | AF17: 12 | AG17: 12 | AH17: 12 | AI17: 12 | AJ17: 0 | AK17: 0 | AL17: 0 | AM17: 0 | AN17: 0 | AO17: 0 | AP17: 0 | AQ17: 0 | OV17: cr-1787763837290-77aw3|night
B18: =SUM(L18:AQ18) | D18: =B18*E18 | E18: ='Rate Tables'!C11 | F18: ST | L18: =IF(L$6="","",IF(OR(WEEKDAY(L$6,1)=1,WEEKDAY(L$6,1)=7),0,MIN(8,L17)*L16)) | M18: =IF(M$6="","",IF(OR(WEEKDAY(M$6,1)=1,WEEKDAY(M$6,1)=7),0,MIN(8,M17)*M16)) | N18: =IF(N$6="","",IF(OR(WEEKDAY(N$6,1)=1,WEEKDAY(N$6,1)=7),0,MIN(8,N17)*N16)) | O18: =IF(O$6="","",IF(OR(WEEKDAY(O$6,1)=1,WEEKDAY(O$6,1)=7),0,MIN(8,O17)*O16)) | P18: =IF(P$6="","",IF(OR(WEEKDAY(P$6,1)=1,WEEKDAY(P$6,1)=7),0,MIN(8,P17)*P16)) | Q18: =IF(Q$6="","",IF(OR(WEEKDAY(Q$6,1)=1,WEEKDAY(Q$6,1)=7),0,MIN(8,Q17)*Q16)) | R18: =IF(R$6="","",IF(OR(WEEKDAY(R$6,1)=1,WEEKDAY(R$6,1)=7),0,MIN(8,R17)*R16)) | S18: =IF(S$6="","",IF(OR(WEEKDAY(S$6,1)=1,WEEKDAY(S$6,1)=7),0,MIN(8,S17)*S16)) | ... AQ18: =IF(AQ$6="","",IF(OR(WEEKDAY(AQ$6,1)=1,WEEKDAY(AQ$6,1)=7),0,MIN(8,AQ17)*AQ16)) | OV18: cr-1787763837290-77aw3|night
B19: =SUM(L19:AQ19) | D19: =B19*E19 | E19: ='Rate Tables'!D11 | F19: OT | L19: =IF(L$6="","",IF(WEEKDAY(L$6,1)=1,0,IF(WEEKDAY(L$6,1)=7,L17*L16,MAX(0,L17-8)*L16))) | M19: =IF(M$6="","",IF(WEEKDAY(M$6,1)=1,0,IF(WEEKDAY(M$6,1)=7,M17*M16,MAX(0,M17-8)*M16))) | N19: =IF(N$6="","",IF(WEEKDAY(N$6,1)=1,0,IF(WEEKDAY(N$6,1)=7,N17*N16,MAX(0,N17-8)*N16))) | O19: =IF(O$6="","",IF(WEEKDAY(O$6,1)=1,0,IF(WEEKDAY(O$6,1)=7,O17*O16,MAX(0,O17-8)*O16))) | P19: =IF(P$6="","",IF(WEEKDAY(P$6,1)=1,0,IF(WEEKDAY(P$6,1)=7,P17*P16,MAX(0,P17-8)*P16))) | Q19: =IF(Q$6="","",IF(WEEKDAY(Q$6,1)=1,0,IF(WEEKDAY(Q$6,1)=7,Q17*Q16,MAX(0,Q17-8)*Q16))) | R19: =IF(R$6="","",IF(WEEKDAY(R$6,1)=1,0,IF(WEEKDAY(R$6,1)=7,R17*R16,MAX(0,R17-8)*R16))) | S19: =IF(S$6="","",IF(WEEKDAY(S$6,1)=1,0,IF(WEEKDAY(S$6,1)=7,S17*S16,MAX(0,S17-8)*S16))) | ... AQ19: =IF(AQ$6="","",IF(WEEKDAY(AQ$6,1)=1,0,IF(WEEKDAY(AQ$6,1)=7,AQ17*AQ16,MAX(0,AQ17-8)*AQ16))) | OV19: cr-1787763837290-77aw3|night
B20: =SUM(L20:AQ20) | D20: =B20*E20 | E20: ='Rate Tables'!E11 | F20: DT | L20: =IF(L$6="","",IF(WEEKDAY(L$6,1)=1,L17*L16,0)) | M20: =IF(M$6="","",IF(WEEKDAY(M$6,1)=1,M17*M16,0)) | N20: =IF(N$6="","",IF(WEEKDAY(N$6,1)=1,N17*N16,0)) | O20: =IF(O$6="","",IF(WEEKDAY(O$6,1)=1,O17*O16,0)) | P20: =IF(P$6="","",IF(WEEKDAY(P$6,1)=1,P17*P16,0)) | Q20: =IF(Q$6="","",IF(WEEKDAY(Q$6,1)=1,Q17*Q16,0)) | R20: =IF(R$6="","",IF(WEEKDAY(R$6,1)=1,R17*R16,0)) | S20: =IF(S$6="","",IF(WEEKDAY(S$6,1)=1,S17*S16,0)) | ... AQ20: =IF(AQ$6="","",IF(WEEKDAY(AQ$6,1)=1,AQ17*AQ16,0)) | OV20: cr-1787763837290-77aw3|night
B21: =SUM(L21:AQ21) | D21: =B21*E21 | E21: 130 | F21: PD | L21: 2 | M21: 2 | N21: 2 | O21: 2 | P21: 2 | Q21: 0 | R21: 0 | S21: 2 | T21: 2 | U21: 2 | V21: 2 | W21: 2 | X21: 2 | Y21: 2 | Z21: 2 | AA21: 2 | AB21: 2 | AC21: 2 | AD21: 2 | AE21: 2 | AF21: 2 | AG21: 2 | AH21: 2 | AI21: 2 | AJ21: 0 | AK21: 0 | AL21: 0 | AM21: 0 | AN21: 0 | AO21: 0 | AP21: 0 | AQ21: 0 | OV21: cr-1787763837290-77aw3|night
A22: TOTAL | B22: =SUM(B7,B15) | D22: =SUM(D13,D21) | G22: =SUM(G7,G15) | H22: =SUM(H7,H15) | I22: =SUM(I7,I15) | J22: =SUM(J7,J15) | K22: =SUM(K7,K15)

Sheet Direct
A1: HIT SQUAD / PROJECT CONTROLS
A2: Produced by Hit Squad Project Controls · Confidential estimate package
A3: Madison CAT 2 (Pit Stop)
A4: Phillips 66 · Wood River — Roxana, IL · East Coast (PCA0001103)
A5: Produced Sep 4, 2026 | B5: 46269.757
A6: Shift | B6: Total Billable | C6: Position | D6: Sub Total $ | E6: Rate | F6: Type | G6: ST Hrs | H6: OT Hrs | I6: DT Hrs | J6: PD Days | K6: Labor $ | L6: 46286 | M6: =L6+1 | N6: =M6+1 | O6: =N6+1 | P6: =O6+1 | Q6: =P6+1 | R6: =Q6+1 | S6: =R6+1 | T6: =S6+1 | ... AQ6: =AP6+1
A7: DAYSHIFT | B7: =G7+H7+I7 | C7: Pipefitter Journeyman | D7: =K7 | F7: TITLE | G7: =B10 | H7: =B11 | I7: =B12 | J7: =B13 | K7: =D10+D11+D12 | OV7: cr-1787764763277-txdnp|day
F8: HC | L8: 8 | M8: 8 | N8: 8 | O8: 8 | P8: 8 | Q8: 0 | R8: 0 | S8: 8 | T8: 8 | U8: 8 | V8: 18 | W8: 18 | X8: 18 | Y8: 18 | Z8: 18 | AA8: 18 | AB8: 18 | AC8: 18 | AD8: 18 | AE8: 18 | AF8: 18 | AG8: 18 | AH8: 18 | AI8: 18 | AJ8: 8 | AK8: 8 | AL8: 0 | AM8: 0 | AN8: 8 | AO8: 8 | AP8: 8 | AQ8: 8 | OV8: cr-1787764763277-txdnp|day
A9: Enter Hours Per shift Here | F9: HPS | L9: 8 | M9: 8 | N9: 8 | O9: 8 | P9: 8 | Q9: 0 | R9: 0 | S9: 8 | T9: 8 | U9: 8 | V9: 12 | W9: 12 | X9: 12 | Y9: 12 | Z9: 12 | AA9: 12 | AB9: 12 | AC9: 12 | AD9: 12 | AE9: 12 | AF9: 12 | AG9: 12 | AH9: 12 | AI9: 12 | AJ9: 8 | AK9: 8 | AL9: 0 | AM9: 0 | AN9: 8 | AO9: 8 | AP9: 8 | AQ9: 8 | OV9: cr-1787764763277-txdnp|day
B10: =SUM(L10:AQ10) | D10: =B10*E10 | E10: ='Rate Tables'!C12 | F10: ST | L10: =IF(L$6="","",IF(OR(WEEKDAY(L$6,1)=1,WEEKDAY(L$6,1)=7),0,MIN(8,L9)*L8)) | M10: =IF(M$6="","",IF(OR(WEEKDAY(M$6,1)=1,WEEKDAY(M$6,1)=7),0,MIN(8,M9)*M8)) | N10: =IF(N$6="","",IF(OR(WEEKDAY(N$6,1)=1,WEEKDAY(N$6,1)=7),0,MIN(8,N9)*N8)) | O10: =IF(O$6="","",IF(OR(WEEKDAY(O$6,1)=1,WEEKDAY(O$6,1)=7),0,MIN(8,O9)*O8)) | P10: =IF(P$6="","",IF(OR(WEEKDAY(P$6,1)=1,WEEKDAY(P$6,1)=7),0,MIN(8,P9)*P8)) | Q10: =IF(Q$6="","",IF(OR(WEEKDAY(Q$6,1)=1,WEEKDAY(Q$6,1)=7),0,MIN(8,Q9)*Q8)) | R10: =IF(R$6="","",IF(OR(WEEKDAY(R$6,1)=1,WEEKDAY(R$6,1)=7),0,MIN(8,R9)*R8)) | S10: =IF(S$6="","",IF(OR(WEEKDAY(S$6,1)=1,WEEKDAY(S$6,1)=7),0,MIN(8,S9)*S8)) | ... AQ10: =IF(AQ$6="","",IF(OR(WEEKDAY(AQ$6,1)=1,WEEKDAY(AQ$6,1)=7),0,MIN(8,AQ9)*AQ8)) | OV10: cr-1787764763277-txdnp|day
B11: =SUM(L11:AQ11) | D11: =B11*E11 | E11: ='Rate Tables'!D12 | F11: OT | L11: =IF(L$6="","",IF(WEEKDAY(L$6,1)=1,0,IF(WEEKDAY(L$6,1)=7,L9*L8,MAX(0,L9-8)*L8))) | M11: =IF(M$6="","",IF(WEEKDAY(M$6,1)=1,0,IF(WEEKDAY(M$6,1)=7,M9*M8,MAX(0,M9-8)*M8))) | N11: =IF(N$6="","",IF(WEEKDAY(N$6,1)=1,0,IF(WEEKDAY(N$6,1)=7,N9*N8,MAX(0,N9-8)*N8))) | O11: =IF(O$6="","",IF(WEEKDAY(O$6,1)=1,0,IF(WEEKDAY(O$6,1)=7,O9*O8,MAX(0,O9-8)*O8))) | P11: =IF(P$6="","",IF(WEEKDAY(P$6,1)=1,0,IF(WEEKDAY(P$6,1)=7,P9*P8,MAX(0,P9-8)*P8))) | Q11: =IF(Q$6="","",IF(WEEKDAY(Q$6,1)=1,0,IF(WEEKDAY(Q$6,1)=7,Q9*Q8,MAX(0,Q9-8)*Q8))) | R11: =IF(R$6="","",IF(WEEKDAY(R$6,1)=1,0,IF(WEEKDAY(R$6,1)=7,R9*R8,MAX(0,R9-8)*R8))) | S11: =IF(S$6="","",IF(WEEKDAY(S$6,1)=1,0,IF(WEEKDAY(S$6,1)=7,S9*S8,MAX(0,S9-8)*S8))) | ... AQ11: =IF(AQ$6="","",IF(WEEKDAY(AQ$6,1)=1,0,IF(WEEKDAY(AQ$6,1)=7,AQ9*AQ8,MAX(0,AQ9-8)*AQ8))) | OV11: cr-1787764763277-txdnp|day
B12: =SUM(L12:AQ12) | D12: =B12*E12 | E12: ='Rate Tables'!E12 | F12: DT | L12: =IF(L$6="","",IF(WEEKDAY(L$6,1)=1,L9*L8,0)) | M12: =IF(M$6="","",IF(WEEKDAY(M$6,1)=1,M9*M8,0)) | N12: =IF(N$6="","",IF(WEEKDAY(N$6,1)=1,N9*N8,0)) | O12: =IF(O$6="","",IF(WEEKDAY(O$6,1)=1,O9*O8,0)) | P12: =IF(P$6="","",IF(WEEKDAY(P$6,1)=1,P9*P8,0)) | Q12: =IF(Q$6="","",IF(WEEKDAY(Q$6,1)=1,Q9*Q8,0)) | R12: =IF(R$6="","",IF(WEEKDAY(R$6,1)=1,R9*R8,0)) | S12: =IF(S$6="","",IF(WEEKDAY(S$6,1)=1,S9*S8,0)) | ... AQ12: =IF(AQ$6="","",IF(WEEKDAY(AQ$6,1)=1,AQ9*AQ8,0)) | OV12: cr-1787764763277-txdnp|day
B13: =SUM(L13:AQ13) | D13: =B13*E13 | E13: 130 | F13: PD | L13: 5 | M13: 5 | N13: 5 | O13: 5 | P13: 5 | Q13: 0 | R13: 0 | S13: 5 | T13: 5 | U13: 5 | V13: 10 | W13: 10 | X13: 10 | Y13: 10 | Z13: 10 | AA13: 10 | AB13: 10 | AC13: 10 | AD13: 10 | AE13: 10 | AF13: 10 | AG13: 10 | AH13: 10 | AI13: 10 | AJ13: 5 | AK13: 5 | AL13: 0 | AM13: 0 | AN13: 5 | AO13: 5 | AP13: 5 | AQ13: 5 | OV13: cr-1787764763277-txdnp|day
A15: NIGHTSHIFT | B15: =G15+H15+I15 | C15: Pipefitter Journeyman | D15: =K15 | F15: TITLE | G15: =B18 | H15: =B19 | I15: =B20 | J15: =B21 | K15: =D18+D19+D20 | OV15: cr-1787764763277-txdnp|night
F16: HC | L16: 0 | M16: 0 | N16: 0 | O16: 0 | P16: 0 | Q16: 0 | R16: 0 | S16: 0 | T16: 0 | U16: 0 | V16: 16 | W16: 16 | X16: 16 | Y16: 16 | Z16: 16 | AA16: 16 | AB16: 16 | AC16: 16 | AD16: 16 | AE16: 16 | AF16: 16 | AG16: 16 | AH16: 16 | AI16: 16 | AJ16: 0 | AK16: 0 | AL16: 0 | AM16: 0 | AN16: 0 | AO16: 0 | AP16: 0 | AQ16: 0 | OV16: cr-1787764763277-txdnp|night
A17: Enter Hours Per shift Here | F17: HPS | L17: 0 | M17: 0 | N17: 0 | O17: 0 | P17: 0 | Q17: 0 | R17: 0 | S17: 0 | T17: 0 | U17: 0 | V17: 12 | W17: 12 | X17: 12 | Y17: 12 | Z17: 12 | AA17: 12 | AB17: 12 | AC17: 12 | AD17: 12 | AE17: 12 | AF17: 12 | AG17: 12 | AH17: 12 | AI17: 12 | AJ17: 0 | AK17: 0 | AL17: 0 | AM17: 0 | AN17: 0 | AO17: 0 | AP17: 0 | AQ17: 0 | OV17: cr-1787764763277-txdnp|night
B18: =SUM(L18:AQ18) | D18: =B18*E18 | E18: ='Rate Tables'!C12 | F18: ST | L18: =IF(L$6="","",IF(OR(WEEKDAY(L$6,1)=1,WEEKDAY(L$6,1)=7),0,MIN(8,L17)*L16)) | M18: =IF(M$6="","",IF(OR(WEEKDAY(M$6,1)=1,WEEKDAY(M$6,1)=7),0,MIN(8,M17)*M16)) | N18: =IF(N$6="","",IF(OR(WEEKDAY(N$6,1)=1,WEEKDAY(N$6,1)=7),0,MIN(8,N17)*N16)) | O18: =IF(O$6="","",IF(OR(WEEKDAY(O$6,1)=1,WEEKDAY(O$6,1)=7),0,MIN(8,O17)*O16)) | P18: =IF(P$6="","",IF(OR(WEEKDAY(P$6,1)=1,WEEKDAY(P$6,1)=7),0,MIN(8,P17)*P16)) | Q18: =IF(Q$6="","",IF(OR(WEEKDAY(Q$6,1)=1,WEEKDAY(Q$6,1)=7),0,MIN(8,Q17)*Q16)) | R18: =IF(R$6="","",IF(OR(WEEKDAY(R$6,1)=1,WEEKDAY(R$6,1)=7),0,MIN(8,R17)*R16)) | S18: =IF(S$6="","",IF(OR(WEEKDAY(S$6,1)=1,WEEKDAY(S$6,1)=7),0,MIN(8,S17)*S16)) | ... AQ18: =IF(AQ$6="","",IF(OR(WEEKDAY(AQ$6,1)=1,WEEKDAY(AQ$6,1)=7),0,MIN(8,AQ17)*AQ16)) | OV18: cr-1787764763277-txdnp|night
B19: =SUM(L19:AQ19) | D19: =B19*E19 | E19: ='Rate Tables'!D12 | F19: OT | L19: =IF(L$6="","",IF(WEEKDAY(L$6,1)=1,0,IF(WEEKDAY(L$6,1)=7,L17*L16,MAX(0,L17-8)*L16))) | M19: =IF(M$6="","",IF(WEEKDAY(M$6,1)=1,0,IF(WEEKDAY(M$6,1)=7,M17*M16,MAX(0,M17-8)*M16))) | N19: =IF(N$6="","",IF(WEEKDAY(N$6,1)=1,0,IF(WEEKDAY(N$6,1)=7,N17*N16,MAX(0,N17-8)*N16))) | O19: =IF(O$6="","",IF(WEEKDAY(O$6,1)=1,0,IF(WEEKDAY(O$6,1)=7,O17*O16,MAX(0,O17-8)*O16))) | P19: =IF(P$6="","",IF(WEEKDAY(P$6,1)=1,0,IF(WEEKDAY(P$6,1)=7,P17*P16,MAX(0,P17-8)*P16))) | Q19: =IF(Q$6="","",IF(WEEKDAY(Q$6,1)=1,0,IF(WEEKDAY(Q$6,1)=7,Q17*Q16,MAX(0,Q17-8)*Q16))) | R19: =IF(R$6="","",IF(WEEKDAY(R$6,1)=1,0,IF(WEEKDAY(R$6,1)=7,R17*R16,MAX(0,R17-8)*R16))) | S19: =IF(S$6="","",IF(WEEKDAY(S$6,1)=1,0,IF(WEEKDAY(S$6,1)=7,S17*S16,MAX(0,S17-8)*S16))) | ... AQ19: =IF(AQ$6="","",IF(WEEKDAY(AQ$6,1)=1,0,IF(WEEKDAY(AQ$6,1)=7,AQ17*AQ16,MAX(0,AQ17-8)*AQ16))) | OV19: cr-1787764763277-txdnp|night
B20: =SUM(L20:AQ20) | D20: =B20*E20 | E20: ='Rate Tables'!E12 | F20: DT | L20: =IF(L$6="","",IF(WEEKDAY(L$6,1)=1,L17*L16,0)) | M20: =IF(M$6="","",IF(WEEKDAY(M$6,1)=1,M17*M16,0)) | N20: =IF(N$6="","",IF(WEEKDAY(N$6,1)=1,N17*N16,0)) | O20: =IF(O$6="","",IF(WEEKDAY(O$6,1)=1,O17*O16,0)) | P20: =IF(P$6="","",IF(WEEKDAY(P$6,1)=1,P17*P16,0)) | Q20: =IF(Q$6="","",IF(WEEKDAY(Q$6,1)=1,Q17*Q16,0)) | R20: =IF(R$6="","",IF(WEEKDAY(R$6,1)=1,R17*R16,0)) | S20: =IF(S$6="","",IF(WEEKDAY(S$6,1)=1,S17*S16,0)) | ... AQ20: =IF(AQ$6="","",IF(WEEKDAY(AQ$6,1)=1,AQ17*AQ16,0)) | OV20: cr-1787764763277-txdnp|night
B21: =SUM(L21:AQ21) | D21: =B21*E21 | E21: 130 | F21: PD | L21: 0 | M21: 0 | N21: 0 | O21: 0 | P21: 0 | Q21: 0 | R21: 0 | S21: 0 | T21: 0 | U21: 0 | V21: 1 | W21: 1 | X21: 1 | Y21: 1 | Z21: 1 | AA21: 1 | AB21: 1 | AC21: 1 | AD21: 1 | AE21: 1 | AF21: 1 | AG21: 1 | AH21: 1 | AI21: 1 | AJ21: 0 | AK21: 0 | AL21: 0 | AM21: 0 | AN21: 0 | AO21: 0 | AP21: 0 | AQ21: 0 | OV21: cr-1787764763277-txdnp|night
A22: TOTAL | B22: =SUM(B7,B15) | D22: =SUM(D13,D21) | G22: =SUM(G7,G15) | H22: =SUM(H7,H15) | I22: =SUM(I7,I15) | J22: =SUM(J7,J15) | K22: =SUM(K7,K15)

Sheet Support
A1: HIT SQUAD / PROJECT CONTROLS
A2: Produced by Hit Squad Project Controls · Confidential estimate package
A3: Madison CAT 2 (Pit Stop)
A4: Phillips 66 · Wood River — Roxana, IL · East Coast (PCA0001103)
A5: Produced Sep 4, 2026 | B5: 46269.757
A6: Shift | B6: Total Billable | C6: Position | D6: Sub Total $ | E6: Rate | F6: Type | G6: ST Hrs | H6: OT Hrs | I6: DT Hrs | J6: PD Days | K6: Labor $ | L6: 46286 | M6: =L6+1 | N6: =M6+1 | O6: =N6+1 | P6: =O6+1 | Q6: =P6+1 | R6: =Q6+1 | S6: =R6+1 | T6: =S6+1 | ... AQ6: =AP6+1
A7: DAYSHIFT | B7: =G7+H7+I7 | C7: Tool Room Attendant | D7: =K7 | F7: TITLE | G7: =B10 | H7: =B11 | I7: =B12 | J7: =B13 | K7: =D10+D11+D12 | OV7: sup-1787768630004-lgj97|day
F8: HC | L8: 1 | M8: 1 | N8: 1 | O8: 1 | P8: 1 | Q8: 0 | R8: 0 | S8: 1 | T8: 1 | U8: 1 | V8: 1 | W8: 1 | X8: 1 | Y8: 1 | Z8: 1 | AA8: 1 | AB8: 1 | AC8: 1 | AD8: 1 | AE8: 1 | AF8: 1 | AG8: 1 | AH8: 1 | AI8: 1 | AJ8: 1 | AK8: 1 | AL8: 0 | AM8: 0 | AN8: 1 | AO8: 1 | AP8: 1 | AQ8: 1 | OV8: sup-1787768630004-lgj97|day
A9: Enter Hours Per shift Here | F9: HPS | L9: 8 | M9: 8 | N9: 8 | O9: 8 | P9: 8 | Q9: 0 | R9: 0 | S9: 8 | T9: 8 | U9: 8 | V9: 12 | W9: 12 | X9: 12 | Y9: 12 | Z9: 12 | AA9: 12 | AB9: 12 | AC9: 12 | AD9: 12 | AE9: 12 | AF9: 12 | AG9: 12 | AH9: 12 | AI9: 12 | AJ9: 8 | AK9: 8 | AL9: 0 | AM9: 0 | AN9: 8 | AO9: 8 | AP9: 8 | AQ9: 8 | OV9: sup-1787768630004-lgj97|day
B10: =SUM(L10:AQ10) | D10: =B10*E10 | E10: ='Rate Tables'!C13 | F10: ST | L10: =IF(L$6="","",IF(OR(WEEKDAY(L$6,1)=1,WEEKDAY(L$6,1)=7),0,MIN(8,L9)*L8)) | M10: =IF(M$6="","",IF(OR(WEEKDAY(M$6,1)=1,WEEKDAY(M$6,1)=7),0,MIN(8,M9)*M8)) | N10: =IF(N$6="","",IF(OR(WEEKDAY(N$6,1)=1,WEEKDAY(N$6,1)=7),0,MIN(8,N9)*N8)) | O10: =IF(O$6="","",IF(OR(WEEKDAY(O$6,1)=1,WEEKDAY(O$6,1)=7),0,MIN(8,O9)*O8)) | P10: =IF(P$6="","",IF(OR(WEEKDAY(P$6,1)=1,WEEKDAY(P$6,1)=7),0,MIN(8,P9)*P8)) | Q10: =IF(Q$6="","",IF(OR(WEEKDAY(Q$6,1)=1,WEEKDAY(Q$6,1)=7),0,MIN(8,Q9)*Q8)) | R10: =IF(R$6="","",IF(OR(WEEKDAY(R$6,1)=1,WEEKDAY(R$6,1)=7),0,MIN(8,R9)*R8)) | S10: =IF(S$6="","",IF(OR(WEEKDAY(S$6,1)=1,WEEKDAY(S$6,1)=7),0,MIN(8,S9)*S8)) | ... AQ10: =IF(AQ$6="","",IF(OR(WEEKDAY(AQ$6,1)=1,WEEKDAY(AQ$6,1)=7),0,MIN(8,AQ9)*AQ8)) | OV10: sup-1787768630004-lgj97|day
B11: =SUM(L11:AQ11) | D11: =B11*E11 | E11: ='Rate Tables'!D13 | F11: OT | L11: =IF(L$6="","",IF(WEEKDAY(L$6,1)=1,0,IF(WEEKDAY(L$6,1)=7,L9*L8,MAX(0,L9-8)*L8))) | M11: =IF(M$6="","",IF(WEEKDAY(M$6,1)=1,0,IF(WEEKDAY(M$6,1)=7,M9*M8,MAX(0,M9-8)*M8))) | N11: =IF(N$6="","",IF(WEEKDAY(N$6,1)=1,0,IF(WEEKDAY(N$6,1)=7,N9*N8,MAX(0,N9-8)*N8))) | O11: =IF(O$6="","",IF(WEEKDAY(O$6,1)=1,0,IF(WEEKDAY(O$6,1)=7,O9*O8,MAX(0,O9-8)*O8))) | P11: =IF(P$6="","",IF(WEEKDAY(P$6,1)=1,0,IF(WEEKDAY(P$6,1)=7,P9*P8,MAX(0,P9-8)*P8))) | Q11: =IF(Q$6="","",IF(WEEKDAY(Q$6,1)=1,0,IF(WEEKDAY(Q$6,1)=7,Q9*Q8,MAX(0,Q9-8)*Q8))) | R11: =IF(R$6="","",IF(WEEKDAY(R$6,1)=1,0,IF(WEEKDAY(R$6,1)=7,R9*R8,MAX(0,R9-8)*R8))) | S11: =IF(S$6="","",IF(WEEKDAY(S$6,1)=1,0,IF(WEEKDAY(S$6,1)=7,S9*S8,MAX(0,S9-8)*S8))) | ... AQ11: =IF(AQ$6="","",IF(WEEKDAY(AQ$6,1)=1,0,IF(WEEKDAY(AQ$6,1)=7,AQ9*AQ8,MAX(0,AQ9-8)*AQ8))) | OV11: sup-1787768630004-lgj97|day
B12: =SUM(L12:AQ12) | D12: =B12*E12 | E12: ='Rate Tables'!E13 | F12: DT | L12: =IF(L$6="","",IF(WEEKDAY(L$6,1)=1,L9*L8,0)) | M12: =IF(M$6="","",IF(WEEKDAY(M$6,1)=1,M9*M8,0)) | N12: =IF(N$6="","",IF(WEEKDAY(N$6,1)=1,N9*N8,0)) | O12: =IF(O$6="","",IF(WEEKDAY(O$6,1)=1,O9*O8,0)) | P12: =IF(P$6="","",IF(WEEKDAY(P$6,1)=1,P9*P8,0)) | Q12: =IF(Q$6="","",IF(WEEKDAY(Q$6,1)=1,Q9*Q8,0)) | R12: =IF(R$6="","",IF(WEEKDAY(R$6,1)=1,R9*R8,0)) | S12: =IF(S$6="","",IF(WEEKDAY(S$6,1)=1,S9*S8,0)) | ... AQ12: =IF(AQ$6="","",IF(WEEKDAY(AQ$6,1)=1,AQ9*AQ8,0)) | OV12: sup-1787768630004-lgj97|day
B13: =SUM(L13:AQ13) | D13: =B13*E13 | E13: 130 | F13: PD | L13: 1 | M13: 1 | N13: 1 | O13: 1 | P13: 1 | Q13: 0 | R13: 0 | S13: 1 | T13: 1 | U13: 1 | V13: 1 | W13: 1 | X13: 1 | Y13: 1 | Z13: 1 | AA13: 1 | AB13: 1 | AC13: 1 | AD13: 1 | AE13: 1 | AF13: 1 | AG13: 1 | AH13: 1 | AI13: 1 | AJ13: 1 | AK13: 1 | AL13: 0 | AM13: 0 | AN13: 1 | AO13: 1 | AP13: 1 | AQ13: 1 | OV13: sup-1787768630004-lgj97|day
A15: NIGHTSHIFT | B15: =G15+H15+I15 | C15: Tool Room Attendant | D15: =K15 | F15: TITLE | G15: =B18 | H15: =B19 | I15: =B20 | J15: =B21 | K15: =D18+D19+D20 | OV15: sup-1787768630004-lgj97|night
F16: HC | L16: 0 | M16: 0 | N16: 0 | O16: 0 | P16: 0 | Q16: 0 | R16: 0 | S16: 0 | T16: 0 | U16: 0 | V16: 1 | W16: 1 | X16: 1 | Y16: 1 | Z16: 1 | AA16: 1 | AB16: 1 | AC16: 1 | AD16: 1 | AE16: 1 | AF16: 1 | AG16: 1 | AH16: 1 | AI16: 1 | AJ16: 0 | AK16: 0 | AL16: 0 | AM16: 0 | AN16: 0 | AO16: 0 | AP16: 0 | AQ16: 0 | OV16: sup-1787768630004-lgj97|night
A17: Enter Hours Per shift Here | F17: HPS | L17: 0 | M17: 0 | N17: 0 | O17: 0 | P17: 0 | Q17: 0 | R17: 0 | S17: 0 | T17: 0 | U17: 0 | V17: 12 | W17: 12 | X17: 12 | Y17: 12 | Z17: 12 | AA17: 12 | AB17: 12 | AC17: 12 | AD17: 12 | AE17: 12 | AF17: 12 | AG17: 12 | AH17: 12 | AI17: 12 | AJ17: 0 | AK17: 0 | AL17: 0 | AM17: 0 | AN17: 0 | AO17: 0 | AP17: 0 | AQ17: 0 | OV17: sup-1787768630004-lgj97|night
B18: =SUM(L18:AQ18) | D18: =B18*E18 | E18: ='Rate Tables'!C13 | F18: ST | L18: =IF(L$6="","",IF(OR(WEEKDAY(L$6,1)=1,WEEKDAY(L$6,1)=7),0,MIN(8,L17)*L16)) | M18: =IF(M$6="","",IF(OR(WEEKDAY(M$6,1)=1,WEEKDAY(M$6,1)=7),0,MIN(8,M17)*M16)) | N18: =IF(N$6="","",IF(OR(WEEKDAY(N$6,1)=1,WEEKDAY(N$6,1)=7),0,MIN(8,N17)*N16)) | O18: =IF(O$6="","",IF(OR(WEEKDAY(O$6,1)=1,WEEKDAY(O$6,1)=7),0,MIN(8,O17)*O16)) | P18: =IF(P$6="","",IF(OR(WEEKDAY(P$6,1)=1,WEEKDAY(P$6,1)=7),0,MIN(8,P17)*P16)) | Q18: =IF(Q$6="","",IF(OR(WEEKDAY(Q$6,1)=1,WEEKDAY(Q$6,1)=7),0,MIN(8,Q17)*Q16)) | R18: =IF(R$6="","",IF(OR(WEEKDAY(R$6,1)=1,WEEKDAY(R$6,1)=7),0,MIN(8,R17)*R16)) | S18: =IF(S$6="","",IF(OR(WEEKDAY(S$6,1)=1,WEEKDAY(S$6,1)=7),0,MIN(8,S17)*S16)) | ... AQ18: =IF(AQ$6="","",IF(OR(WEEKDAY(AQ$6,1)=1,WEEKDAY(AQ$6,1)=7),0,MIN(8,AQ17)*AQ16)) | OV18: sup-1787768630004-lgj97|night
B19: =SUM(L19:AQ19) | D19: =B19*E19 | E19: ='Rate Tables'!D13 | F19: OT | L19: =IF(L$6="","",IF(WEEKDAY(L$6,1)=1,0,IF(WEEKDAY(L$6,1)=7,L17*L16,MAX(0,L17-8)*L16))) | M19: =IF(M$6="","",IF(WEEKDAY(M$6,1)=1,0,IF(WEEKDAY(M$6,1)=7,M17*M16,MAX(0,M17-8)*M16))) | N19: =IF(N$6="","",IF(WEEKDAY(N$6,1)=1,0,IF(WEEKDAY(N$6,1)=7,N17*N16,MAX(0,N17-8)*N16))) | O19: =IF(O$6="","",IF(WEEKDAY(O$6,1)=1,0,IF(WEEKDAY(O$6,1)=7,O17*O16,MAX(0,O17-8)*O16))) | P19: =IF(P$6="","",IF(WEEKDAY(P$6,1)=1,0,IF(WEEKDAY(P$6,1)=7,P17*P16,MAX(0,P17-8)*P16))) | Q19: =IF(Q$6="","",IF(WEEKDAY(Q$6,1)=1,0,IF(WEEKDAY(Q$6,1)=7,Q17*Q16,MAX(0,Q17-8)*Q16))) | R19: =IF(R$6="","",IF(WEEKDAY(R$6,1)=1,0,IF(WEEKDAY(R$6,1)=7,R17*R16,MAX(0,R17-8)*R16))) | S19: =IF(S$6="","",IF(WEEKDAY(S$6,1)=1,0,IF(WEEKDAY(S$6,1)=7,S17*S16,MAX(0,S17-8)*S16))) | ... AQ19: =IF(AQ$6="","",IF(WEEKDAY(AQ$6,1)=1,0,IF(WEEKDAY(AQ$6,1)=7,AQ17*AQ16,MAX(0,AQ17-8)*AQ16))) | OV19: sup-1787768630004-lgj97|night
B20: =SUM(L20:AQ20) | D20: =B20*E20 | E20: ='Rate Tables'!E13 | F20: DT | L20: =IF(L$6="","",IF(WEEKDAY(L$6,1)=1,L17*L16,0)) | M20: =IF(M$6="","",IF(WEEKDAY(M$6,1)=1,M17*M16,0)) | N20: =IF(N$6="","",IF(WEEKDAY(N$6,1)=1,N17*N16,0)) | O20: =IF(O$6="","",IF(WEEKDAY(O$6,1)=1,O17*O16,0)) | P20: =IF(P$6="","",IF(WEEKDAY(P$6,1)=1,P17*P16,0)) | Q20: =IF(Q$6="","",IF(WEEKDAY(Q$6,1)=1,Q17*Q16,0)) | R20: =IF(R$6="","",IF(WEEKDAY(R$6,1)=1,R17*R16,0)) | S20: =IF(S$6="","",IF(WEEKDAY(S$6,1)=1,S17*S16,0)) | ... AQ20: =IF(AQ$6="","",IF(WEEKDAY(AQ$6,1)=1,AQ17*AQ16,0)) | OV20: sup-1787768630004-lgj97|night
B21: =SUM(L21:AQ21) | D21: =B21*E21 | E21: 130 | F21: PD | L21: 0 | M21: 0 | N21: 0 | O21: 0 | P21: 0 | Q21: 0 | R21: 0 | S21: 0 | T21: 0 | U21: 0 | V21: 1 | W21: 1 | X21: 1 | Y21: 1 | Z21: 1 | AA21: 1 | AB21: 1 | AC21: 1 | AD21: 1 | AE21: 1 | AF21: 1 | AG21: 1 | AH21: 1 | AI21: 1 | AJ21: 0 | AK21: 0 | AL21: 0 | AM21: 0 | AN21: 0 | AO21: 0 | AP21: 0 | AQ21: 0 | OV21: sup-1787768630004-lgj97|night
A22: TOTAL | B22: =SUM(B7,B15) | D22: =SUM(D13,D21) | G22: =SUM(G7,G15) | H22: =SUM(H7,H15) | I22: =SUM(I7,I15) | J22: =SUM(J7,J15) | K22: =SUM(K7,K15)

Sheet COE
A1: HIT SQUAD / PROJECT CONTROLS
A2: Produced by Hit Squad Project Controls · Confidential estimate package
A3: Madison CAT 2 (Pit Stop)
A4: Phillips 66 · Wood River — Roxana, IL · East Coast (PCA0001103)
A5: Produced Sep 4, 2026 | B5: 46269.757
A6: Item | B6: Period | C6: Qty | D6: Periods | E6: Rate $ | F6: Freight $ | G6: Total $
A7: RAD GUN TORQUE | B7: monthly | C7: 5 | D7: 3 | E7: 4464 | F7: 0 | G7: =C7*D7*E7+F7
A8: WELDER ARC 100-300 AMP ELECTRIC | B8: monthly | C8: 3 | D8: 2 | E8: 612 | F8: 0 | G8: =C8*D8*E8+F8
A9: TRUCK CREW | B9: monthly | C9: 3 | D9: 2 | E9: 936 | F9: 0 | G9: =C9*D9*E9+F9
A10: PUMP TORQUE CONSOLE 10K PSI | B10: daily | C10: 1 | D10: 32 | E10: 1160 | F10: 0 | G10: =C10*D10*E10+F10
A11: TOTAL | G11: =SUM(G7:G10)

Sheet Staff Travel Cost
A1: HIT SQUAD / PROJECT CONTROLS
A2: Produced by Hit Squad Project Controls · Confidential estimate package
A3: Madison CAT 2 (Pit Stop)
A4: Phillips 66 · Wood River — Roxana, IL · East Coast (PCA0001103)
A5: Produced Sep 4, 2026 | B5: 46269.757
A6: Kind | B6: Travelers | C6: Miles | D6: $ / mile | E6: Total $
A7: Staff | B7: 6 | C7: 1500 | D7: 0.76 | E7: =B7*C7*D7
A8: TOTAL | E8: =SUM(E7:E7)

Sheet Misc Costs
A1: HIT SQUAD / PROJECT CONTROLS
A2: Produced by Hit Squad Project Controls · Confidential estimate package
A3: Madison CAT 2 (Pit Stop)
A4: Phillips 66 · Wood River — Roxana, IL · East Coast (PCA0001103)
A5: Produced Sep 4, 2026 | B5: 46269.757
A6: Item | B6: Description | C6: Qty | D6: Each $ | E6: Total $
A7: Weld / cut gas | B7: Mixed shielding | C7: 3.5 | D7: 1000 | E7: =C7*D7
A8: Fire blanket | B8: Welding blanket | C8: 1 | D8: 1200 | E8: =C8*D8
A9: Anti-seize | B9: Jet Lube | C9: 1 | D9: 6000 | E9: =C9*D9
A10: TOTAL | E10: =SUM(E7:E9)

Sheet Rate Tables
A1: HIT SQUAD / PROJECT CONTROLS
A2: Produced by Hit Squad Project Controls · Confidential estimate package
A3: Madison CAT 2 (Pit Stop)
A4: Phillips 66 · Wood River — Roxana, IL · East Coast (PCA0001103)
A5: Produced Sep 4, 2026 | B5: 46269.757
A6: Craft | B6: COMP BW $ | C6: ST Bill $ | D6: OT Bill $ | E6: DT Bill $ | F6: PD Rate
A7: Superintendent PF 01 | C7: 111.67 | D7: 156.21 | E7: 200.75 | F7: 140
A8: COORDINATOR QA-QC 1 | B8: 64 | C8: 105.76 | D8: 143.77 | E8: 181.79 | F8: 140
A9: COORDINATOR SAFETY 01 | B9: 52.5 | C9: 91.02 | D9: 122.2 | E9: 153.39 | F9: 140
A10: Pipefitter General Foreman | B10: 58.84 | C10: 111.22 | D10: 156.31 | E10: 201.4 | F10: 140
A11: Pipefitter Foreman | C11: 105.28 | D11: 147.5 | E11: 189.72 | F11: 130
A12: Pipefitter Journeyman | B12: 49.03 | C12: 99.33 | D12: 138.69 | E12: 178.05 | F12: 130
A13: Boilermaker Journeyman | B13: 45.6 | C13: 108.38 | D13: 152.78 | E13: 197.19 | F13: 130
